Workbook

Sheet Data
A1: Module | B1: Raw LOC | C1: Code LOC | D1: Effort factor
A2: Client — Components | B2: 11577 | C2: 9873 | D2: 1
A3: Client — Pages | B3: 11250 | C3: 9833 | D3: 1
A4: Server — Other | B4: 5502 | C4: 4135 | D4: 1
A5: Server — Core, auth & API | B5: 3841 | C5: 2894 | D5: 1
A6: Docs | B6: 4004 | C6: 3376 | D6: 0.594
A7: Server — Data & Looker | B7: 2406 | C7: 1927 | D7: 1
A8: Tests | B8: 2494 | C8: 1918 | D8: 1
A9: Server — Campaign engine | B9: 2443 | C9: 1893 | D9: 1
A10: Client — Lib & shell | B10: 1986 | C10: 1496 | D10: 1
A11: Server — AI & insights | B11: 1143 | C11: 933 | D11: 1
A12: Client — Editor | B12: 987 | C12: 871 | D12: 1
A13: Client — Tiles | B13: 932 | C13: 752 | D13: 1
... A27: Server — Fixtures & data | B27: 127 | C27: 127 | D27: 0.3

Sheet Tracker
A1: Build-Value Tracker — replacement-cost estimate
A2: What it would plausibly cost to commission this build from a senior contractor at the rate below. This is a REPLACEMENT-COST estimate — NOT revenue, NOT realised value. "Build only" = writing the code; "Full delivery" applies the delivery multiplier for design, testing, QA, UAT and PM. Always read it with the sensitivity band: the Net LOC/day assumption moves the answer more than the rate, so quote the band, never a single headline figure.
A4: Assumptions — edit these
A5: Hourly rate (R/hour) | B5: 650
A6: Hours per day | B6: 8
A7: Net LOC per day | B7: 150
A8: Delivery multiplier (design, test, QA, UAT, PM) | B8: 2
A10: Per-module value
A11: Module | B11: Equiv LOC | C11: Engineer-days | D11: Engineer-hours | E11: Build value (R)
A12: =IF(Data!A2="","",Data!A2) | B12: =IF(Data!C2="","",Data!C2*Data!D2) | C12: =IF(B12="","",B12/$B$7) | D12: =IF(C12="","",C12*$B$6) | E12: =IF(D12="","",D12*$B$5)
A13: =IF(Data!A3="","",Data!A3) | B13: =IF(Data!C3="","",Data!C3*Data!D3) | C13: =IF(B13="","",B13/$B$7) | D13: =IF(C13="","",C13*$B$6) | E13: =IF(D13="","",D13*$B$5)
A14: =IF(Data!A4="","",Data!A4) | B14: =IF(Data!C4="","",Data!C4*Data!D4) | C14: =IF(B14="","",B14/$B$7) | D14: =IF(C14="","",C14*$B$6) | E14: =IF(D14="","",D14*$B$5)
A15: =IF(Data!A5="","",Data!A5) | B15: =IF(Data!C5="","",Data!C5*Data!D5) | C15: =IF(B15="","",B15/$B$7) | D15: =IF(C15="","",C15*$B$6) | E15: =IF(D15="","",D15*$B$5)
A16: =IF(Data!A6="","",Data!A6) | B16: =IF(Data!C6="","",Data!C6*Data!D6) | C16: =IF(B16="","",B16/$B$7) | D16: =IF(C16="","",C16*$B$6) | E16: =IF(D16="","",D16*$B$5)
A17: =IF(Data!A7="","",Data!A7) | B17: =IF(Data!C7="","",Data!C7*Data!D7) | C17: =IF(B17="","",B17/$B$7) | D17: =IF(C17="","",C17*$B$6) | E17: =IF(D17="","",D17*$B$5)
A18: =IF(Data!A8="","",Data!A8) | B18: =IF(Data!C8="","",Data!C8*Data!D8) | C18: =IF(B18="","",B18/$B$7) | D18: =IF(C18="","",C18*$B$6) | E18: =IF(D18="","",D18*$B$5)
A19: =IF(Data!A9="","",Data!A9) | B19: =IF(Data!C9="","",Data!C9*Data!D9) | C19: =IF(B19="","",B19/$B$7) | D19: =IF(C19="","",C19*$B$6) | E19: =IF(D19="","",D19*$B$5)
A20: =IF(Data!A10="","",Data!A10) | B20: =IF(Data!C10="","",Data!C10*Data!D10) | C20: =IF(B20="","",B20/$B$7) | D20: =IF(C20="","",C20*$B$6) | E20: =IF(D20="","",D20*$B$5)
A21: =IF(Data!A11="","",Data!A11) | B21: =IF(Data!C11="","",Data!C11*Data!D11) | C21: =IF(B21="","",B21/$B$7) | D21: =IF(C21="","",C21*$B$6) | E21: =IF(D21="","",D21*$B$5)
A22: =IF(Data!A12="","",Data!A12) | B22: =IF(Data!C12="","",Data!C12*Data!D12) | C22: =IF(B22="","",B22/$B$7) | D22: =IF(C22="","",C22*$B$6) | E22: =IF(D22="","",D22*$B$5)
A23: =IF(Data!A13="","",Data!A13) | B23: =IF(Data!C13="","",Data!C13*Data!D13) | C23: =IF(B23="","",B23/$B$7) | D23: =IF(C23="","",C23*$B$6) | E23: =IF(D23="","",D23*$B$5)
... A111: =IF(Data!A101="","",Data!A101) | B111: =IF(Data!C101="","",Data!C101*Data!D101) | C111: =IF(B111="","",B111/$B$7) | D111: =IF(C111="","",C111*$B$6) | E111: =IF(D111="","",D111*$B$5)
A112: TOTAL | B112: =SUM(B12:B111) | C112: =SUM(C12:C111) | D112: =SUM(D12:D111) | E112: =SUM(E12:E111)
A114: Headline — current assumptions
A115: Build only (writing the code) | B115: =$E$112
A116: Full delivery (× delivery multiplier) | B116: =$E$112*$B$8 | C116: =design, testing, QA, UAT, PM on top of build
A118: Sensitivity — total value by Net LOC/day (the dominant assumption)
A119: Net LOC/day | B119: Engineer-days | C119: Build value (R) | D119: Full delivery (R)
A120: 100 | B120: =$B$112/100 | C120: =$B$112/100*$B$6*$B$5 | D120: =$B$112/100*$B$6*$B$5*$B$8
A121: 150 | B121: =$B$112/150 | C121: =$B$112/150*$B$6*$B$5 | D121: =$B$112/150*$B$6*$B$5*$B$8 | E121: ← current
A122: 250 | B122: =$B$112/250 | C122: =$B$112/250*$B$6*$B$5 | D122: =$B$112/250*$B$6*$B$5*$B$8
A125: How to update
A126: 1. Run: python3 update_tracker.py /path/to/project --xlsx Build_Value_Tracker.xlsx
A127: 2. The script rewrites the Data tab (Module, Raw LOC, Code LOC, Effort factor) and writes loc_data.csv.
A128: 3. This Tracker tab recalculates automatically when the file is (re)opened.
A129: 4. Google Sheets: import loc_data.csv into the Data tab (replace existing data); this tab recalculates the same way.
A130: 5. Adjust the yellow cells (rate, hours/day, net LOC/day, delivery multiplier) at any time — everything below updates.
A131: 6. Effort factors discount generated/repetitive content (SVG ~0.30, JSON ~0.30, HTML ~0.55, CSS/MD ~0.60, app logic 1.0),
A132: so the figure is a defensible replacement cost, not a vanity line count.
A133: 7. Delivery multiplier: "Build only" is just writing code; "Full delivery" multiplies it for design, testing, QA, UAT and PM.
...
